Traceback (most recent call last):
  File "/Users/sergiosilveramurcia/Conda/miniconda3/envs/TimesSeries/lib/python3.9/site-packages/jupyter_cache/executors/utils.py", line 58, in single_nb_execution
    executenb(
  File "/Users/sergiosilveramurcia/Conda/miniconda3/envs/TimesSeries/lib/python3.9/site-packages/nbclient/client.py", line 1305, in execute
    return NotebookClient(nb=nb, resources=resources, km=km, **kwargs).execute()
  File "/Users/sergiosilveramurcia/Conda/miniconda3/envs/TimesSeries/lib/python3.9/site-packages/jupyter_core/utils/__init__.py", line 166, in wrapped
    return loop.run_until_complete(inner)
  File "/Users/sergiosilveramurcia/Conda/miniconda3/envs/TimesSeries/lib/python3.9/asyncio/base_events.py", line 647, in run_until_complete
    return future.result()
  File "/Users/sergiosilveramurcia/Conda/miniconda3/envs/TimesSeries/lib/python3.9/site-packages/nbclient/client.py", line 705, in async_execute
    await self.async_execute_cell(
  File "/Users/sergiosilveramurcia/Conda/miniconda3/envs/TimesSeries/lib/python3.9/site-packages/nbclient/client.py", line 1058, in async_execute_cell
    await self._check_raise_for_error(cell, cell_index, exec_reply)
  File "/Users/sergiosilveramurcia/Conda/miniconda3/envs/TimesSeries/lib/python3.9/site-packages/nbclient/client.py", line 914, in _check_raise_for_error
    raise CellExecutionError.from_cell_and_msg(cell, exec_reply_content)
nbclient.exceptions.CellExecutionError: An error occurred while executing the following cell:
------------------
# Reads data from PB1
QUERY = "SELECT * FROM SCHEMA.TABLE"
data = hana.read_data(QUERY)
------------------


[0;31m---------------------------------------------------------------------------[0m
[0;31mNameError[0m                                 Traceback (most recent call last)
Cell [0;32mIn[2], line 3[0m
[1;32m      1[0m [38;5;66;03m# Reads data from PB1[39;00m
[1;32m      2[0m QUERY [38;5;241m=[39m [38;5;124m"[39m[38;5;124mSELECT * FROM SCHEMA.TABLE[39m[38;5;124m"[39m
[0;32m----> 3[0m data [38;5;241m=[39m [43mhana[49m[38;5;241m.[39mread_data(QUERY)

[0;31mNameError[0m: name 'hana' is not defined

